Workbook

Sheet LISTADO
A1: EVALUACIÓN DE ESPECIES · Antioquia Natural · Comité Científico Asesor
A2: # | B2: Fecha | C2: Evaluador(es) | D2: Nombre científico | E2: Nombre común (ES) | F2: Grupo | G2: Familia taxonómica | H2: Subregiones presentes | I2: P1 · IUCN (máx. 20) | J2: P2 · Endemismo (máx. 20) | K2: P3 · Rol ecológico (máx. 15) | L2: P4 · Rep. geográfica (máx. 15) | M2: P5a · Reconocibilidad (máx. 5) | N2: P5b · Historia natural (máx. 5) | O2: P5c · Valor cultural (máx. 5) | P2: P6 · Foto disponible (máx. 10) | Q2: P7 · Diversidad taxonómica (máx. 5) | R2: TOTAL (/100) | S2: Categoría | T2: Decisión comité | U2: Fuente fotográfica | V2: Notas
A3: 1 | R3: ==IF(I3="","",IFERROR(IFERROR(VLOOKUP(I3,Listas!$A$15:$B$20,2,0),0)+IFERROR(VLOOKUP(J3,Listas!$A$24:$B$29,2,0),0)+IFERROR(VLOOKUP(K3,Listas!$A$33:$B$37,2,0),0)+IFERROR(VLOOKUP(L3,Listas!$A$41:$B$44,2,0),0)+IFERROR(VLOOKUP(M3,Listas!$A$48:$B$50,2,0),0)+IFERROR(VLOOKUP(N3,Listas!$A$54:$B$56,2,0),0)+IFERROR(VLOOKUP(O3,Listas!$A$60:$B$62,2,0),0)+IFERROR(VLOOKUP(P3,Listas!$A$66:$B$69,2,0),0)+IFERROR(VLOOKUP(Q3,Listas!$A$73:$B$76,2,0),0),0)) | S3: ==IF(I3="","",IF(R3>=80,"Prioritaria",IF(R3>=60,"Recomendada",IF(R3>=40,"Condicional","Lista de espera"))))
A4: 2 | R4: ==IF(I4="","",IFERROR(IFERROR(VLOOKUP(I4,Listas!$A$15:$B$20,2,0),0)+IFERROR(VLOOKUP(J4,Listas!$A$24:$B$29,2,0),0)+IFERROR(VLOOKUP(K4,Listas!$A$33:$B$37,2,0),0)+IFERROR(VLOOKUP(L4,Listas!$A$41:$B$44,2,0),0)+IFERROR(VLOOKUP(M4,Listas!$A$48:$B$50,2,0),0)+IFERROR(VLOOKUP(N4,Listas!$A$54:$B$56,2,0),0)+IFERROR(VLOOKUP(O4,Listas!$A$60:$B$62,2,0),0)+IFERROR(VLOOKUP(P4,Listas!$A$66:$B$69,2,0),0)+IFERROR(VLOOKUP(Q4,Listas!$A$73:$B$76,2,0),0),0)) | S4: ==IF(I4="","",IF(R4>=80,"Prioritaria",IF(R4>=60,"Recomendada",IF(R4>=40,"Condicional","Lista de espera"))))
A5: 3 | R5: ==IF(I5="","",IFERROR(IFERROR(VLOOKUP(I5,Listas!$A$15:$B$20,2,0),0)+IFERROR(VLOOKUP(J5,Listas!$A$24:$B$29,2,0),0)+IFERROR(VLOOKUP(K5,Listas!$A$33:$B$37,2,0),0)+IFERROR(VLOOKUP(L5,Listas!$A$41:$B$44,2,0),0)+IFERROR(VLOOKUP(M5,Listas!$A$48:$B$50,2,0),0)+IFERROR(VLOOKUP(N5,Listas!$A$54:$B$56,2,0),0)+IFERROR(VLOOKUP(O5,Listas!$A$60:$B$62,2,0),0)+IFERROR(VLOOKUP(P5,Listas!$A$66:$B$69,2,0),0)+IFERROR(VLOOKUP(Q5,Listas!$A$73:$B$76,2,0),0),0)) | S5: ==IF(I5="","",IF(R5>=80,"Prioritaria",IF(R5>=60,"Recomendada",IF(R5>=40,"Condicional","Lista de espera"))))
A6: 4 | R6: ==IF(I6="","",IFERROR(IFERROR(VLOOKUP(I6,Listas!$A$15:$B$20,2,0),0)+IFERROR(VLOOKUP(J6,Listas!$A$24:$B$29,2,0),0)+IFERROR(VLOOKUP(K6,Listas!$A$33:$B$37,2,0),0)+IFERROR(VLOOKUP(L6,Listas!$A$41:$B$44,2,0),0)+IFERROR(VLOOKUP(M6,Listas!$A$48:$B$50,2,0),0)+IFERROR(VLOOKUP(N6,Listas!$A$54:$B$56,2,0),0)+IFERROR(VLOOKUP(O6,Listas!$A$60:$B$62,2,0),0)+IFERROR(VLOOKUP(P6,Listas!$A$66:$B$69,2,0),0)+IFERROR(VLOOKUP(Q6,Listas!$A$73:$B$76,2,0),0),0)) | S6: ==IF(I6="","",IF(R6>=80,"Prioritaria",IF(R6>=60,"Recomendada",IF(R6>=40,"Condicional","Lista de espera"))))
A7: 5 | R7: ==IF(I7="","",IFERROR(IFERROR(VLOOKUP(I7,Listas!$A$15:$B$20,2,0),0)+IFERROR(VLOOKUP(J7,Listas!$A$24:$B$29,2,0),0)+IFERROR(VLOOKUP(K7,Listas!$A$33:$B$37,2,0),0)+IFERROR(VLOOKUP(L7,Listas!$A$41:$B$44,2,0),0)+IFERROR(VLOOKUP(M7,Listas!$A$48:$B$50,2,0),0)+IFERROR(VLOOKUP(N7,Listas!$A$54:$B$56,2,0),0)+IFERROR(VLOOKUP(O7,Listas!$A$60:$B$62,2,0),0)+IFERROR(VLOOKUP(P7,Listas!$A$66:$B$69,2,0),0)+IFERROR(VLOOKUP(Q7,Listas!$A$73:$B$76,2,0),0),0)) | S7: ==IF(I7="","",IF(R7>=80,"Prioritaria",IF(R7>=60,"Recomendada",IF(R7>=40,"Condicional","Lista de espera"))))
A8: 6 | R8: ==IF(I8="","",IFERROR(IFERROR(VLOOKUP(I8,Listas!$A$15:$B$20,2,0),0)+IFERROR(VLOOKUP(J8,Listas!$A$24:$B$29,2,0),0)+IFERROR(VLOOKUP(K8,Listas!$A$33:$B$37,2,0),0)+IFERROR(VLOOKUP(L8,Listas!$A$41:$B$44,2,0),0)+IFERROR(VLOOKUP(M8,Listas!$A$48:$B$50,2,0),0)+IFERROR(VLOOKUP(N8,Listas!$A$54:$B$56,2,0),0)+IFERROR(VLOOKUP(O8,Listas!$A$60:$B$62,2,0),0)+IFERROR(VLOOKUP(P8,Listas!$A$66:$B$69,2,0),0)+IFERROR(VLOOKUP(Q8,Listas!$A$73:$B$76,2,0),0),0)) | S8: ==IF(I8="","",IF(R8>=80,"Prioritaria",IF(R8>=60,"Recomendada",IF(R8>=40,"Condicional","Lista de espera"))))
A9: 7 | R9: ==IF(I9="","",IFERROR(IFERROR(VLOOKUP(I9,Listas!$A$15:$B$20,2,0),0)+IFERROR(VLOOKUP(J9,Listas!$A$24:$B$29,2,0),0)+IFERROR(VLOOKUP(K9,Listas!$A$33:$B$37,2,0),0)+IFERROR(VLOOKUP(L9,Listas!$A$41:$B$44,2,0),0)+IFERROR(VLOOKUP(M9,Listas!$A$48:$B$50,2,0),0)+IFERROR(VLOOKUP(N9,Listas!$A$54:$B$56,2,0),0)+IFERROR(VLOOKUP(O9,Listas!$A$60:$B$62,2,0),0)+IFERROR(VLOOKUP(P9,Listas!$A$66:$B$69,2,0),0)+IFERROR(VLOOKUP(Q9,Listas!$A$73:$B$76,2,0),0),0)) | S9: ==IF(I9="","",IF(R9>=80,"Prioritaria",IF(R9>=60,"Recomendada",IF(R9>=40,"Condicional","Lista de espera"))))
A10: 8 | R10: ==IF(I10="","",IFERROR(IFERROR(VLOOKUP(I10,Listas!$A$15:$B$20,2,0),0)+IFERROR(VLOOKUP(J10,Listas!$A$24:$B$29,2,0),0)+IFERROR(VLOOKUP(K10,Listas!$A$33:$B$37,2,0),0)+IFERROR(VLOOKUP(L10,Listas!$A$41:$B$44,2,0),0)+IFERROR(VLOOKUP(M10,Listas!$A$48:$B$50,2,0),0)+IFERROR(VLOOKUP(N10,Listas!$A$54:$B$56,2,0),0)+IFERROR(VLOOKUP(O10,Listas!$A$60:$B$62,2,0),0)+IFERROR(VLOOKUP(P10,Listas!$A$66:$B$69,2,0),0)+IFERROR(VLOOKUP(Q10,Listas!$A$73:$B$76,2,0),0),0)) | S10: ==IF(I10="","",IF(R10>=80,"Prioritaria",IF(R10>=60,"Recomendada",IF(R10>=40,"Condicional","Lista de espera"))))
A11: 9 | R11: ==IF(I11="","",IFERROR(IFERROR(VLOOKUP(I11,Listas!$A$15:$B$20,2,0),0)+IFERROR(VLOOKUP(J11,Listas!$A$24:$B$29,2,0),0)+IFERROR(VLOOKUP(K11,Listas!$A$33:$B$37,2,0),0)+IFERROR(VLOOKUP(L11,Listas!$A$41:$B$44,2,0),0)+IFERROR(VLOOKUP(M11,Listas!$A$48:$B$50,2,0),0)+IFERROR(VLOOKUP(N11,Listas!$A$54:$B$56,2,0),0)+IFERROR(VLOOKUP(O11,Listas!$A$60:$B$62,2,0),0)+IFERROR(VLOOKUP(P11,Listas!$A$66:$B$69,2,0),0)+IFERROR(VLOOKUP(Q11,Listas!$A$73:$B$76,2,0),0),0)) | S11: ==IF(I11="","",IF(R11>=80,"Prioritaria",IF(R11>=60,"Recomendada",IF(R11>=40,"Condicional","Lista de espera"))))
A12: 10 | R12: ==IF(I12="","",IFERROR(IFERROR(VLOOKUP(I12,Listas!$A$15:$B$20,2,0),0)+IFERROR(VLOOKUP(J12,Listas!$A$24:$B$29,2,0),0)+IFERROR(VLOOKUP(K12,Listas!$A$33:$B$37,2,0),0)+IFERROR(VLOOKUP(L12,Listas!$A$41:$B$44,2,0),0)+IFERROR(VLOOKUP(M12,Listas!$A$48:$B$50,2,0),0)+IFERROR(VLOOKUP(N12,Listas!$A$54:$B$56,2,0),0)+IFERROR(VLOOKUP(O12,Listas!$A$60:$B$62,2,0),0)+IFERROR(VLOOKUP(P12,Listas!$A$66:$B$69,2,0),0)+IFERROR(VLOOKUP(Q12,Listas!$A$73:$B$76,2,0),0),0)) | S12: ==IF(I12="","",IF(R12>=80,"Prioritaria",IF(R12>=60,"Recomendada",IF(R12>=40,"Condicional","Lista de espera"))))
A13: 11 | R13: ==IF(I13="","",IFERROR(IFERROR(VLOOKUP(I13,Listas!$A$15:$B$20,2,0),0)+IFERROR(VLOOKUP(J13,Listas!$A$24:$B$29,2,0),0)+IFERROR(VLOOKUP(K13,Listas!$A$33:$B$37,2,0),0)+IFERROR(VLOOKUP(L13,Listas!$A$41:$B$44,2,0),0)+IFERROR(VLOOKUP(M13,Listas!$A$48:$B$50,2,0),0)+IFERROR(VLOOKUP(N13,Listas!$A$54:$B$56,2,0),0)+IFERROR(VLOOKUP(O13,Listas!$A$60:$B$62,2,0),0)+IFERROR(VLOOKUP(P13,Listas!$A$66:$B$69,2,0),0)+IFERROR(VLOOKUP(Q13,Listas!$A$73:$B$76,2,0),0),0)) | S13: ==IF(I13="","",IF(R13>=80,"Prioritaria",IF(R13>=60,"Recomendada",IF(R13>=40,"Condicional","Lista de espera"))))
A14: 12 | R14: ==IF(I14="","",IFERROR(IFERROR(VLOOKUP(I14,Listas!$A$15:$B$20,2,0),0)+IFERROR(VLOOKUP(J14,Listas!$A$24:$B$29,2,0),0)+IFERROR(VLOOKUP(K14,Listas!$A$33:$B$37,2,0),0)+IFERROR(VLOOKUP(L14,Listas!$A$41:$B$44,2,0),0)+IFERROR(VLOOKUP(M14,Listas!$A$48:$B$50,2,0),0)+IFERROR(VLOOKUP(N14,Listas!$A$54:$B$56,2,0),0)+IFERROR(VLOOKUP(O14,Listas!$A$60:$B$62,2,0),0)+IFERROR(VLOOKUP(P14,Listas!$A$66:$B$69,2,0),0)+IFERROR(VLOOKUP(Q14,Listas!$A$73:$B$76,2,0),0),0)) | S14: ==IF(I14="","",IF(R14>=80,"Prioritaria",IF(R14>=60,"Recomendada",IF(R14>=40,"Condicional","Lista de espera"))))
... A202: 200 | R202: ==IF(I202="","",IFERROR(IFERROR(VLOOKUP(I202,Listas!$A$15:$B$20,2,0),0)+IFERROR(VLOOKUP(J202,Listas!$A$24:$B$29,2,0),0)+IFERROR(VLOOKUP(K202,Listas!$A$33:$B$37,2,0),0)+IFERROR(VLOOKUP(L202,Listas!$A$41:$B$44,2,0),0)+IFERROR(VLOOKUP(M202,Listas!$A$48:$B$50,2,0),0)+IFERROR(VLOOKUP(N202,Listas!$A$54:$B$56,2,0),0)+IFERROR(VLOOKUP(O202,Listas!$A$60:$B$62,2,0),0)+IFERROR(VLOOKUP(P202,Listas!$A$66:$B$69,2,0),0)+IFERROR(VLOOKUP(Q202,Listas!$A$73:$B$76,2,0),0),0)) | S202: ==IF(I202="","",IF(R202>=80,"Prioritaria",IF(R202>=60,"Recomendada",IF(R202>=40,"Condicional","Lista de espera"))))

Sheet INSTRUCCIONES
A1: INSTRUCCIONES — Plantilla de Evaluación de Especies · Antioquia Natural
A3: ¿Cómo usar esta plantilla?
A4: 1. Ir a la hoja LISTADO.
A5: 2. Completar una fila por especie evaluada.
A6: 3. Ingresar los datos de identificación: nombre científico, nombre común, grupo, familia y subregiones (columnas A–H).
A7: 4. En las columnas P1–P7 (I–Q) abrir el desplegable y seleccionar la descripción que corresponda a la especie.
A8: 5. El TOTAL (col R) y la Categoría (col S) se calculan automáticamente con colores.
A9: 6. Registrar la Decisión del comité (col T), la fuente fotográfica (U) y observaciones (V).
A10: 7. Usar los filtros de la fila 2 para ver por grupo, categoría, decisión o evaluador.
A11: 8. P4 (representación geográfica) y P7 (diversidad taxonómica) son dinámicos — revisar al final de cada sesión.
A13: Interpretación del puntaje total (/100)
A14: Rango | B14: Pts | C14: Categoría | D14: Decisión recomendada
A15: 80 – 100 | B15: ≥80 | C15: Prioritaria | D15: Debe estar en versión 1.0 sin excepción
A16: 60 – 79 | B16: ≥60 | C16: Recomendada | D16: Incluir dentro del cupo disponible del grupo
A17: 40 – 59 | B17: ≥40 | C17: Condicional | D17: Incluir si hay cupo y cumple cuota mínima
A18: < 40 | B18: <40 | C18: Lista de espera | D18: Reservar para Fase 2 o reemplazos
A20: P1 · IUCN — (máx. 20)
A21: Descripción (opción del desplegable) | B21: Pts | C21: Notas
A22: CR · En peligro crítico | B22: 20
A23: EN · En peligro | B23: 17
A24: VU · Vulnerable | B24: 13
A25: NT · Casi amenazada | B25: 9
A26: DD · Datos insuficientes | B26: 7
A27: LC · Preocupación menor | B27: 4
A29: P2 · Endemismo — (máx. 20)
A30: Descripción (opción del desplegable) | B30: Pts | C30: Notas
A31: Endémica de Antioquia | B31: 20
A32: Endémica región andina | B32: 16
A33: Endémica de Colombia | B33: 13
A34: Cuasi-endémica | B34: 9
A35: Nativa no endémica | B35: 4
A36: Introducida / exótica | B36: 0
A38: P3 · Rol ecológico — (máx. 15)
A39: Descripción (opción del desplegable) | B39: Pts | C39: Notas
A40: Único o insustituible | B40: 15
A41: Importante con alternativas | B41: 11
A42: Moderado | B42: 7
A43: Genérico | B43: 3
A44: Sin documentar | B44: 1
A46: P4 · Rep. geográfica — (máx. 15)
...

Sheet Listas
A1: Grupos de biodiversidad
A2: Grupo
A3: Aves
A4: Anfibios y Reptiles
A5: Mariposas
A6: Polillas
A7: Mamíferos
A8: Animales Domésticos
A9: Peces de Agua Dulce
A10: Orquídeas
A11: Árboles Nativos
A13: P1 · IUCN — (máx. 20)
A14: Descripción | B14: Puntaje
A15: CR · En peligro crítico | B15: 20
A16: EN · En peligro | B16: 17
A17: VU · Vulnerable | B17: 13
A18: NT · Casi amenazada | B18: 9
A19: DD · Datos insuficientes | B19: 7
A20: LC · Preocupación menor | B20: 4
A22: P2 · Endemismo — (máx. 20)
A23: Descripción | B23: Puntaje
A24: Endémica de Antioquia | B24: 20
A25: Endémica región andina | B25: 16
A26: Endémica de Colombia | B26: 13
A27: Cuasi-endémica | B27: 9
A28: Nativa no endémica | B28: 4
A29: Introducida / exótica | B29: 0
A31: P3 · Rol ecológico — (máx. 15)
A32: Descripción | B32: Puntaje
A33: Único o insustituible | B33: 15
A34: Importante con alternativas | B34: 11
A35: Moderado | B35: 7
A36: Genérico | B36: 3
A37: Sin documentar | B37: 1
A39: P4 · Rep. geográfica — (máx. 15)
A40: Descripción | B40: Puntaje
A41: Representante único de subregión | B41: 15
A42: Subregiones poco representadas | B42: 12
A43: 3 a 5 subregiones | B43: 8
A44: Distribución amplia (6-9 subr.) | B44: 5
...

Sheet RESUMEN
A1: RESUMEN DE EVALUACIÓN · Antioquia Natural · Comité Científico Asesor
A3: Totales generales
A4: Total especies evaluadas | B4: =COUNTA(LISTADO!D3:D202)
A5: Prioritarias (puntaje ≥ 80) | B5: =COUNTIF(LISTADO!S3:S202,"Prioritaria")
A6: Recomendadas (60 – 79 pts) | B6: =COUNTIF(LISTADO!S3:S202,"Recomendada")
A7: Condicionales (40 – 59 pts) | B7: =COUNTIF(LISTADO!S3:S202,"Condicional")
A8: Lista de espera (< 40 pts) | B8: =COUNTIF(LISTADO!S3:S202,"Lista de espera")
A9: Puntaje promedio | B9: =IFERROR(AVERAGEIF(LISTADO!R3:R202,">0"),"-")
A11: Por grupo taxonómico
A12: Grupo | B12: Evaluadas | C12: Prioritaria | D12: Recomendada | E12: Condicional | F12: Lista espera | G12: Promedio
A13: Aves | B13: =COUNTIF(LISTADO!F3:F202,"Aves") | C13: =COUNTIFS(LISTADO!F3:F202,"Aves",LISTADO!S3:S202,"Prioritaria") | D13: =COUNTIFS(LISTADO!F3:F202,"Aves",LISTADO!S3:S202,"Recomendada") | E13: =COUNTIFS(LISTADO!F3:F202,"Aves",LISTADO!S3:S202,"Condicional") | F13: =COUNTIFS(LISTADO!F3:F202,"Aves",LISTADO!S3:S202,"Lista de espera") | G13: =IFERROR(AVERAGEIFS(LISTADO!R3:R202,LISTADO!F3:F202,"Aves",LISTADO!R3:R202,">0"),"-")
A14: Anfibios y Reptiles | B14: =COUNTIF(LISTADO!F3:F202,"Anfibios y Reptiles") | C14: =COUNTIFS(LISTADO!F3:F202,"Anfibios y Reptiles",LISTADO!S3:S202,"Prioritaria") | D14: =COUNTIFS(LISTADO!F3:F202,"Anfibios y Reptiles",LISTADO!S3:S202,"Recomendada") | E14: =COUNTIFS(LISTADO!F3:F202,"Anfibios y Reptiles",LISTADO!S3:S202,"Condicional") | F14: =COUNTIFS(LISTADO!F3:F202,"Anfibios y Reptiles",LISTADO!S3:S202,"Lista de espera") | G14: =IFERROR(AVERAGEIFS(LISTADO!R3:R202,LISTADO!F3:F202,"Anfibios y Reptiles",LISTADO!R3:R202,">0"),"-")
A15: Mariposas | B15: =COUNTIF(LISTADO!F3:F202,"Mariposas") | C15: =COUNTIFS(LISTADO!F3:F202,"Mariposas",LISTADO!S3:S202,"Prioritaria") | D15: =COUNTIFS(LISTADO!F3:F202,"Mariposas",LISTADO!S3:S202,"Recomendada") | E15: =COUNTIFS(LISTADO!F3:F202,"Mariposas",LISTADO!S3:S202,"Condicional") | F15: =COUNTIFS(LISTADO!F3:F202,"Mariposas",LISTADO!S3:S202,"Lista de espera") | G15: =IFERROR(AVERAGEIFS(LISTADO!R3:R202,LISTADO!F3:F202,"Mariposas",LISTADO!R3:R202,">0"),"-")
A16: Polillas | B16: =COUNTIF(LISTADO!F3:F202,"Polillas") | C16: =COUNTIFS(LISTADO!F3:F202,"Polillas",LISTADO!S3:S202,"Prioritaria") | D16: =COUNTIFS(LISTADO!F3:F202,"Polillas",LISTADO!S3:S202,"Recomendada") | E16: =COUNTIFS(LISTADO!F3:F202,"Polillas",LISTADO!S3:S202,"Condicional") | F16: =COUNTIFS(LISTADO!F3:F202,"Polillas",LISTADO!S3:S202,"Lista de espera") | G16: =IFERROR(AVERAGEIFS(LISTADO!R3:R202,LISTADO!F3:F202,"Polillas",LISTADO!R3:R202,">0"),"-")
A17: Mamíferos | B17: =COUNTIF(LISTADO!F3:F202,"Mamíferos") | C17: =COUNTIFS(LISTADO!F3:F202,"Mamíferos",LISTADO!S3:S202,"Prioritaria") | D17: =COUNTIFS(LISTADO!F3:F202,"Mamíferos",LISTADO!S3:S202,"Recomendada") | E17: =COUNTIFS(LISTADO!F3:F202,"Mamíferos",LISTADO!S3:S202,"Condicional") | F17: =COUNTIFS(LISTADO!F3:F202,"Mamíferos",LISTADO!S3:S202,"Lista de espera") | G17: =IFERROR(AVERAGEIFS(LISTADO!R3:R202,LISTADO!F3:F202,"Mamíferos",LISTADO!R3:R202,">0"),"-")
A18: Animales Domésticos | B18: =COUNTIF(LISTADO!F3:F202,"Animales Domésticos") | C18: =COUNTIFS(LISTADO!F3:F202,"Animales Domésticos",LISTADO!S3:S202,"Prioritaria") | D18: =COUNTIFS(LISTADO!F3:F202,"Animales Domésticos",LISTADO!S3:S202,"Recomendada") | E18: =COUNTIFS(LISTADO!F3:F202,"Animales Domésticos",LISTADO!S3:S202,"Condicional") | F18: =COUNTIFS(LISTADO!F3:F202,"Animales Domésticos",LISTADO!S3:S202,"Lista de espera") | G18: =IFERROR(AVERAGEIFS(LISTADO!R3:R202,LISTADO!F3:F202,"Animales Domésticos",LISTADO!R3:R202,">0"),"-")
A19: Peces de Agua Dulce | B19: =COUNTIF(LISTADO!F3:F202,"Peces de Agua Dulce") | C19: =COUNTIFS(LISTADO!F3:F202,"Peces de Agua Dulce",LISTADO!S3:S202,"Prioritaria") | D19: =COUNTIFS(LISTADO!F3:F202,"Peces de Agua Dulce",LISTADO!S3:S202,"Recomendada") | E19: =COUNTIFS(LISTADO!F3:F202,"Peces de Agua Dulce",LISTADO!S3:S202,"Condicional") | F19: =COUNTIFS(LISTADO!F3:F202,"Peces de Agua Dulce",LISTADO!S3:S202,"Lista de espera") | G19: =IFERROR(AVERAGEIFS(LISTADO!R3:R202,LISTADO!F3:F202,"Peces de Agua Dulce",LISTADO!R3:R202,">0"),"-")
A20: Orquídeas | B20: =COUNTIF(LISTADO!F3:F202,"Orquídeas") | C20: =COUNTIFS(LISTADO!F3:F202,"Orquídeas",LISTADO!S3:S202,"Prioritaria") | D20: =COUNTIFS(LISTADO!F3:F202,"Orquídeas",LISTADO!S3:S202,"Recomendada") | E20: =COUNTIFS(LISTADO!F3:F202,"Orquídeas",LISTADO!S3:S202,"Condicional") | F20: =COUNTIFS(LISTADO!F3:F202,"Orquídeas",LISTADO!S3:S202,"Lista de espera") | G20: =IFERROR(AVERAGEIFS(LISTADO!R3:R202,LISTADO!F3:F202,"Orquídeas",LISTADO!R3:R202,">0"),"-")
A21: Árboles Nativos | B21: =COUNTIF(LISTADO!F3:F202,"Árboles Nativos") | C21: =COUNTIFS(LISTADO!F3:F202,"Árboles Nativos",LISTADO!S3:S202,"Prioritaria") | D21: =COUNTIFS(LISTADO!F3:F202,"Árboles Nativos",LISTADO!S3:S202,"Recomendada") | E21: =COUNTIFS(LISTADO!F3:F202,"Árboles Nativos",LISTADO!S3:S202,"Condicional") | F21: =COUNTIFS(LISTADO!F3:F202,"Árboles Nativos",LISTADO!S3:S202,"Lista de espera") | G21: =IFERROR(AVERAGEIFS(LISTADO!R3:R202,LISTADO!F3:F202,"Árboles Nativos",LISTADO!R3:R202,">0"),"-")
A22: TOTAL | B22: =SUM(B13:B21) | C22: =SUM(C13:C21) | D22: =SUM(D13:D21) | E22: =SUM(E13:E21) | F22: =SUM(F13:F21) | G22: =IFERROR(AVERAGEIF(LISTADO!R3:R202,">0"),"-")
A24: Top 150 — mayor puntaje
A25: Pos. | B25: Nombre científico | C25: Nombre común | D25: Grupo | E25: Puntaje | F25: Categoría
A26: 1 | B26: =IFERROR(INDEX(LISTADO!$D$3:$D$202,MATCH(LARGE(LISTADO!$R$3:$R$202,1),LISTADO!$R$3:$R$202,0)),"") | C26: =IFERROR(INDEX(LISTADO!$E$3:$E$202,MATCH(LARGE(LISTADO!$R$3:$R$202,1),LISTADO!$R$3:$R$202,0)),"") | D26: =IFERROR(INDEX(LISTADO!$F$3:$F$202,MATCH(LARGE(LISTADO!$R$3:$R$202,1),LISTADO!$R$3:$R$202,0)),"") | E26: =IFERROR(LARGE(LISTADO!$R$3:$R$202,1),"") | F26: =IFERROR(INDEX(LISTADO!$S$3:$S$202,MATCH(LARGE(LISTADO!$R$3:$R$202,1),LISTADO!$R$3:$R$202,0)),"")
A27: 2 | B27: =IFERROR(INDEX(LISTADO!$D$3:$D$202,MATCH(LARGE(LISTADO!$R$3:$R$202,2),LISTADO!$R$3:$R$202,0)),"") | C27: =IFERROR(INDEX(LISTADO!$E$3:$E$202,MATCH(LARGE(LISTADO!$R$3:$R$202,2),LISTADO!$R$3:$R$202,0)),"") | D27: =IFERROR(INDEX(LISTADO!$F$3:$F$202,MATCH(LARGE(LISTADO!$R$3:$R$202,2),LISTADO!$R$3:$R$202,0)),"") | E27: =IFERROR(LARGE(LISTADO!$R$3:$R$202,2),"") | F27: =IFERROR(INDEX(LISTADO!$S$3:$S$202,MATCH(LARGE(LISTADO!$R$3:$R$202,2),LISTADO!$R$3:$R$202,0)),"")
A28: 3 | B28: =IFERROR(INDEX(LISTADO!$D$3:$D$202,MATCH(LARGE(LISTADO!$R$3:$R$202,3),LISTADO!$R$3:$R$202,0)),"") | C28: =IFERROR(INDEX(LISTADO!$E$3:$E$202,MATCH(LARGE(LISTADO!$R$3:$R$202,3),LISTADO!$R$3:$R$202,0)),"") | D28: =IFERROR(INDEX(LISTADO!$F$3:$F$202,MATCH(LARGE(LISTADO!$R$3:$R$202,3),LISTADO!$R$3:$R$202,0)),"") | E28: =IFERROR(LARGE(LISTADO!$R$3:$R$202,3),"") | F28: =IFERROR(INDEX(LISTADO!$S$3:$S$202,MATCH(LARGE(LISTADO!$R$3:$R$202,3),LISTADO!$R$3:$R$202,0)),"")
A29: 4 | B29: =IFERROR(INDEX(LISTADO!$D$3:$D$202,MATCH(LARGE(LISTADO!$R$3:$R$202,4),LISTADO!$R$3:$R$202,0)),"") | C29: =IFERROR(INDEX(LISTADO!$E$3:$E$202,MATCH(LARGE(LISTADO!$R$3:$R$202,4),LISTADO!$R$3:$R$202,0)),"") | D29: =IFERROR(INDEX(LISTADO!$F$3:$F$202,MATCH(LARGE(LISTADO!$R$3:$R$202,4),LISTADO!$R$3:$R$202,0)),"") | E29: =IFERROR(LARGE(LISTADO!$R$3:$R$202,4),"") | F29: =IFERROR(INDEX(LISTADO!$S$3:$S$202,MATCH(LARGE(LISTADO!$R$3:$R$202,4),LISTADO!$R$3:$R$202,0)),"")
A30: 5 | B30: =IFERROR(INDEX(LISTADO!$D$3:$D$202,MATCH(LARGE(LISTADO!$R$3:$R$202,5),LISTADO!$R$3:$R$202,0)),"") | C30: =IFERROR(INDEX(LISTADO!$E$3:$E$202,MATCH(LARGE(LISTADO!$R$3:$R$202,5),LISTADO!$R$3:$R$202,0)),"") | D30: =IFERROR(INDEX(LISTADO!$F$3:$F$202,MATCH(LARGE(LISTADO!$R$3:$R$202,5),LISTADO!$R$3:$R$202,0)),"") | E30: =IFERROR(LARGE(LISTADO!$R$3:$R$202,5),"") | F30: =IFERROR(INDEX(LISTADO!$S$3:$S$202,MATCH(LARGE(LISTADO!$R$3:$R$202,5),LISTADO!$R$3:$R$202,0)),"")
A31: 6 | B31: =IFERROR(INDEX(LISTADO!$D$3:$D$202,MATCH(LARGE(LISTADO!$R$3:$R$202,6),LISTADO!$R$3:$R$202,0)),"") | C31: =IFERROR(INDEX(LISTADO!$E$3:$E$202,MATCH(LARGE(LISTADO!$R$3:$R$202,6),LISTADO!$R$3:$R$202,0)),"") | D31: =IFERROR(INDEX(LISTADO!$F$3:$F$202,MATCH(LARGE(LISTADO!$R$3:$R$202,6),LISTADO!$R$3:$R$202,0)),"") | E31: =IFERROR(LARGE(LISTADO!$R$3:$R$202,6),"") | F31: =IFERROR(INDEX(LISTADO!$S$3:$S$202,MATCH(LARGE(LISTADO!$R$3:$R$202,6),LISTADO!$R$3:$R$202,0)),"")
A32: 7 | B32: =IFERROR(INDEX(LISTADO!$D$3:$D$202,MATCH(LARGE(LISTADO!$R$3:$R$202,7),LISTADO!$R$3:$R$202,0)),"") | C32: =IFERROR(INDEX(LISTADO!$E$3:$E$202,MATCH(LARGE(LISTADO!$R$3:$R$202,7),LISTADO!$R$3:$R$202,0)),"") | D32: =IFERROR(INDEX(LISTADO!$F$3:$F$202,MATCH(LARGE(LISTADO!$R$3:$R$202,7),LISTADO!$R$3:$R$202,0)),"") | E32: =IFERROR(LARGE(LISTADO!$R$3:$R$202,7),"") | F32: =IFERROR(INDEX(LISTADO!$S$3:$S$202,MATCH(LARGE(LISTADO!$R$3:$R$202,7),LISTADO!$R$3:$R$202,0)),"")
A33: 8 | B33: =IFERROR(INDEX(LISTADO!$D$3:$D$202,MATCH(LARGE(LISTADO!$R$3:$R$202,8),LISTADO!$R$3:$R$202,0)),"") | C33: =IFERROR(INDEX(LISTADO!$E$3:$E$202,MATCH(LARGE(LISTADO!$R$3:$R$202,8),LISTADO!$R$3:$R$202,0)),"") | D33: =IFERROR(INDEX(LISTADO!$F$3:$F$202,MATCH(LARGE(LISTADO!$R$3:$R$202,8),LISTADO!$R$3:$R$202,0)),"") | E33: =IFERROR(LARGE(LISTADO!$R$3:$R$202,8),"") | F33: =IFERROR(INDEX(LISTADO!$S$3:$S$202,MATCH(LARGE(LISTADO!$R$3:$R$202,8),LISTADO!$R$3:$R$202,0)),"")
A34: 9 | B34: =IFERROR(INDEX(LISTADO!$D$3:$D$202,MATCH(LARGE(LISTADO!$R$3:$R$202,9),LISTADO!$R$3:$R$202,0)),"") | C34: =IFERROR(INDEX(LISTADO!$E$3:$E$202,MATCH(LARGE(LISTADO!$R$3:$R$202,9),LISTADO!$R$3:$R$202,0)),"") | D34: =IFERROR(INDEX(LISTADO!$F$3:$F$202,MATCH(LARGE(LISTADO!$R$3:$R$202,9),LISTADO!$R$3:$R$202,0)),"") | E34: =IFERROR(LARGE(LISTADO!$R$3:$R$202,9),"") | F34: =IFERROR(INDEX(LISTADO!$S$3:$S$202,MATCH(LARGE(LISTADO!$R$3:$R$202,9),LISTADO!$R$3:$R$202,0)),"")
A35: 10 | B35: =IFERROR(INDEX(LISTADO!$D$3:$D$202,MATCH(LARGE(LISTADO!$R$3:$R$202,10),LISTADO!$R$3:$R$202,0)),"") | C35: =IFERROR(INDEX(LISTADO!$E$3:$E$202,MATCH(LARGE(LISTADO!$R$3:$R$202,10),LISTADO!$R$3:$R$202,0)),"") | D35: =IFERROR(INDEX(LISTADO!$F$3:$F$202,MATCH(LARGE(LISTADO!$R$3:$R$202,10),LISTADO!$R$3:$R$202,0)),"") | E35: =IFERROR(LARGE(LISTADO!$R$3:$R$202,10),"") | F35: =IFERROR(INDEX(LISTADO!$S$3:$S$202,MATCH(LARGE(LISTADO!$R$3:$R$202,10),LISTADO!$R$3:$R$202,0)),"")
A36: 11 | B36: =IFERROR(INDEX(LISTADO!$D$3:$D$202,MATCH(LARGE(LISTADO!$R$3:$R$202,11),LISTADO!$R$3:$R$202,0)),"") | C36: =IFERROR(INDEX(LISTADO!$E$3:$E$202,MATCH(LARGE(LISTADO!$R$3:$R$202,11),LISTADO!$R$3:$R$202,0)),"") | D36: =IFERROR(INDEX(LISTADO!$F$3:$F$202,MATCH(LARGE(LISTADO!$R$3:$R$202,11),LISTADO!$R$3:$R$202,0)),"") | E36: =IFERROR(LARGE(LISTADO!$R$3:$R$202,11),"") | F36: =IFERROR(INDEX(LISTADO!$S$3:$S$202,MATCH(LARGE(LISTADO!$R$3:$R$202,11),LISTADO!$R$3:$R$202,0)),"")
A37: 12 | B37: =IFERROR(INDEX(LISTADO!$D$3:$D$202,MATCH(LARGE(LISTADO!$R$3:$R$202,12),LISTADO!$R$3:$R$202,0)),"") | C37: =IFERROR(INDEX(LISTADO!$E$3:$E$202,MATCH(LARGE(LISTADO!$R$3:$R$202,12),LISTADO!$R$3:$R$202,0)),"") | D37: =IFERROR(INDEX(LISTADO!$F$3:$F$202,MATCH(LARGE(LISTADO!$R$3:$R$202,12),LISTADO!$R$3:$R$202,0)),"") | E37: =IFERROR(LARGE(LISTADO!$R$3:$R$202,12),"") | F37: =IFERROR(INDEX(LISTADO!$S$3:$S$202,MATCH(LARGE(LISTADO!$R$3:$R$202,12),LISTADO!$R$3:$R$202,0)),"")
A38: 13 | B38: =IFERROR(INDEX(LISTADO!$D$3:$D$202,MATCH(LARGE(LISTADO!$R$3:$R$202,13),LISTADO!$R$3:$R$202,0)),"") | C38: =IFERROR(INDEX(LISTADO!$E$3:$E$202,MATCH(LARGE(LISTADO!$R$3:$R$202,13),LISTADO!$R$3:$R$202,0)),"") | D38: =IFERROR(INDEX(LISTADO!$F$3:$F$202,MATCH(LARGE(LISTADO!$R$3:$R$202,13),LISTADO!$R$3:$R$202,0)),"") | E38: =IFERROR(LARGE(LISTADO!$R$3:$R$202,13),"") | F38: =IFERROR(INDEX(LISTADO!$S$3:$S$202,MATCH(LARGE(LISTADO!$R$3:$R$202,13),LISTADO!$R$3:$R$202,0)),"")
A39: 14 | B39: =IFERROR(INDEX(LISTADO!$D$3:$D$202,MATCH(LARGE(LISTADO!$R$3:$R$202,14),LISTADO!$R$3:$R$202,0)),"") | C39: =IFERROR(INDEX(LISTADO!$E$3:$E$202,MATCH(LARGE(LISTADO!$R$3:$R$202,14),LISTADO!$R$3:$R$202,0)),"") | D39: =IFERROR(INDEX(LISTADO!$F$3:$F$202,MATCH(LARGE(LISTADO!$R$3:$R$202,14),LISTADO!$R$3:$R$202,0)),"") | E39: =IFERROR(LARGE(LISTADO!$R$3:$R$202,14),"") | F39: =IFERROR(INDEX(LISTADO!$S$3:$S$202,MATCH(LARGE(LISTADO!$R$3:$R$202,14),LISTADO!$R$3:$R$202,0)),"")
A40: 15 | B40: =IFERROR(INDEX(LISTADO!$D$3:$D$202,MATCH(LARGE(LISTADO!$R$3:$R$202,15),LISTADO!$R$3:$R$202,0)),"") | C40: =IFERROR(INDEX(LISTADO!$E$3:$E$202,MATCH(LARGE(LISTADO!$R$3:$R$202,15),LISTADO!$R$3:$R$202,0)),"") | D40: =IFERROR(INDEX(LISTADO!$F$3:$F$202,MATCH(LARGE(LISTADO!$R$3:$R$202,15),LISTADO!$R$3:$R$202,0)),"") | E40: =IFERROR(LARGE(LISTADO!$R$3:$R$202,15),"") | F40: =IFERROR(INDEX(LISTADO!$S$3:$S$202,MATCH(LARGE(LISTADO!$R$3:$R$202,15),LISTADO!$R$3:$R$202,0)),"")
A41: 16 | B41: =IFERROR(INDEX(LISTADO!$D$3:$D$202,MATCH(LARGE(LISTADO!$R$3:$R$202,16),LISTADO!$R$3:$R$202,0)),"") | C41: =IFERROR(INDEX(LISTADO!$E$3:$E$202,MATCH(LARGE(LISTADO!$R$3:$R$202,16),LISTADO!$R$3:$R$202,0)),"") | D41: =IFERROR(INDEX(LISTADO!$F$3:$F$202,MATCH(LARGE(LISTADO!$R$3:$R$202,16),LISTADO!$R$3:$R$202,0)),"") | E41: =IFERROR(LARGE(LISTADO!$R$3:$R$202,16),"") | F41: =IFERROR(INDEX(LISTADO!$S$3:$S$202,MATCH(LARGE(LISTADO!$R$3:$R$202,16),LISTADO!$R$3:$R$202,0)),"")
A42: 17 | B42: =IFERROR(INDEX(LISTADO!$D$3:$D$202,MATCH(LARGE(LISTADO!$R$3:$R$202,17),LISTADO!$R$3:$R$202,0)),"") | C42: =IFERROR(INDEX(LISTADO!$E$3:$E$202,MATCH(LARGE(LISTADO!$R$3:$R$202,17),LISTADO!$R$3:$R$202,0)),"") | D42: =IFERROR(INDEX(LISTADO!$F$3:$F$202,MATCH(LARGE(LISTADO!$R$3:$R$202,17),LISTADO!$R$3:$R$202,0)),"") | E42: =IFERROR(LARGE(LISTADO!$R$3:$R$202,17),"") | F42: =IFERROR(INDEX(LISTADO!$S$3:$S$202,MATCH(LARGE(LISTADO!$R$3:$R$202,17),LISTADO!$R$3:$R$202,0)),"")
A43: 18 | B43: =IFERROR(INDEX(LISTADO!$D$3:$D$202,MATCH(LARGE(LISTADO!$R$3:$R$202,18),LISTADO!$R$3:$R$202,0)),"") | C43: =IFERROR(INDEX(LISTADO!$E$3:$E$202,MATCH(LARGE(LISTADO!$R$3:$R$202,18),LISTADO!$R$3:$R$202,0)),"") | D43: =IFERROR(INDEX(LISTADO!$F$3:$F$202,MATCH(LARGE(LISTADO!$R$3:$R$202,18),LISTADO!$R$3:$R$202,0)),"") | E43: =IFERROR(LARGE(LISTADO!$R$3:$R$202,18),"") | F43: =IFERROR(INDEX(LISTADO!$S$3:$S$202,MATCH(LARGE(LISTADO!$R$3:$R$202,18),LISTADO!$R$3:$R$202,0)),"")
...
